<?xml version="1.0" ?>
<!-- =================================================================================== -->
<!-- |    This document was autogenerated by xacro from /root/ros_ws/src/assignment2/urdf/my_robot.xacro | -->
<!-- |    EDITING THIS FILE BY HAND IS NOT RECOMMENDED                                 | -->
<!-- =================================================================================== -->
<robot name="robot2_laser_xacro">
    <!-- materials -->
    <gazebo reference="link_chassis">
        <material>Gazebo/Orange</material>
    </gazebo>
    <gazebo reference="link_left_wheel">
        <material>Gazebo/Blue</material>
    </gazebo>
    <gazebo reference="link_right_wheel">
        <material>Gazebo/Blue</material>
    </gazebo>
    <gazebo reference="arm_link_01">
        <material>Gazebo/Red</material>
    </gazebo>
    <gazebo>
        <plugin filename="libgazebo_ros_diff_drive.so" name="differential_drive_controller">
            <legacyMode>true</legacyMode>
            <alwaysOn>true</alwaysOn>
            <updateRate>20</updateRate>
            <leftJoint>joint_right_wheel</leftJoint>
            <rightJoint>joint_left_wheel</rightJoint>
            <wheelSeparation>0.2</wheelSeparation>
            <wheelDiameter>0.2</wheelDiameter>
            <torque>0.1</torque>
            <commandTopic>cmd_vel</commandTopic>
            <odometryTopic>odom</odometryTopic>
            <odometryFrame>odom</odometryFrame>
            <robotBaseFrame>link_chassis</robotBaseFrame>
        </plugin>
    </gazebo>
    <!-- ros_control plugin -->
    <gazebo>
        <plugin filename="libgazebo_ros_control.so" name="gazebo_ros_control">
            <robotNamespace>/robot2_laser_xacro</robotNamespace>
            <robotSimType>gazebo_ros_control/DefaultRobotHWSim</robotSimType>
            <legacyModeNS>true</legacyModeNS>
        </plugin>
    </gazebo>
    <!-- hokuyo -->
    <gazebo reference="hokuyo_link">
        <sensor name="head_hokuyo_sensor" type="gpu_ray">
            <pose>0 0 0 0 0 0</pose>
            <visualize>false</visualize>
            <update_rate>40</update_rate>
            <ray>
                <scan>
                    <horizontal>
                        <samples>720</samples>
                        <resolution>1</resolution>
                        <min_angle>-1.570796</min_angle>
                        <max_angle>1.570796</max_angle>
                    </horizontal>
                </scan>
                <range>
                    <min>0.10</min>
                    <max>30.0</max>
                    <resolution>0.01</resolution>
                </range>
                <noise>
                    <type>gaussian</type>
                    <!-- Noise parameters based on published spec for Hokuyo laser
               achieving "+-30mm" accuracy at range < 10m.  A mean of 0.0m and
               stddev of 0.01m will put 99.7% of samples within 0.03m of the true
               reading. -->
                    <mean>0.0</mean>
                    <stddev>0.01</stddev>
                </noise>
            </ray>
            <plugin filename="libgazebo_ros_gpu_laser.so" name="gazebo_ros_head_hokuyo_controller">
                <topicName>scan</topicName>
                <frameName>hokuyo_link</frameName>
            </plugin>
        </sensor>
    </gazebo>
    <!-- camera -->
    <gazebo reference="camera_link">
        <sensor name="camera1" type="camera">
            <update_rate>30.0</update_rate>
            <camera name="head">
                <horizontal_fov>1.8</horizontal_fov>
                <image>
                    <width>2000</width>
                    <height>2000</height>
                    <format>R8G8B8</format>
                </image>
                <clip>
                    <near>0.02</near>
                    <far>2000</far>
                </clip>
                <noise>
                    <type>gaussian</type>
                    <mean>0.0</mean>
                    <stddev>0.007</stddev>
                </noise>
            </camera>
            <plugin filename="libgazebo_ros_camera.so" name="camera_controller">
                <alwaysOn>true</alwaysOn>
                <updateRate>0.0</updateRate>
                <cameraName>robot/camera1</cameraName>
                <imageTopicName>image_raw</imageTopicName>
                <cameraInfoTopicName>camera_info</cameraInfoTopicName>
                <frameName>camera_link</frameName>
                <hackBaseline>0.07</hackBaseline>
                <distortionK1>0.0</distortionK1>
                <distortionK2>0.0</distortionK2>
                <distortionK3>0.0</distortionK3>
                <distortionT1>0.0</distortionT1>
                <distortionT2>0.0</distortionT2>
            </plugin>
        </sensor>
    </gazebo>
    <material name="black">
        <color rgba="0.0 0.0 0.0 1.0" />
    </material>
    <material name="blue">
        <color rgba="0.203125 0.23828125 0.28515625 1.0" />
    </material>
    <material name="green">
        <color rgba="0.0 0.8 0.0 1.0" />
    </material>
    <material name="grey">
        <color rgba="0.2 0.2 0.2 1.0" />
    </material>
    <material name="orange">
        <color rgba="1.0 0.423529411765 0.0392156862745 1.0" />
    </material>
    <material name="brown">
        <color rgba="0.870588235294 0.811764705882 0.764705882353 1.0" />
    </material>
    <material name="red">
        <color rgba="0.80078125 0.12890625 0.1328125 1.0" />
    </material>
    <material name="white">
        <color rgba="1.0 1.0 1.0 1.0" />
    </material>
    <link name="link_chassis">
        <!-- pose and inertial -->
        <pose>0 0 0.1 0 0 0</pose>
        
<inertial>
            <mass value="5" />
            <origin rpy="0 0 0" xyz="0 0 0.1" />
            <inertia ixx="0.0395416666667" ixy="0" ixz="0" iyy="0.106208333333" iyz="0" izz="0.106208333333" />
        </inertial>

        <!-- body -->
        <collision name="collision_chassis">
            <geometry>
                <box size="0.25 0.15 0.035" />
            </geometry>
        </collision>
        <visual>
            <origin rpy="0 0 0" xyz="0 0 0" />
            <geometry>
                <box size="0.25 0.15 0.035" />
            </geometry>
            <material name="blue" />
        </visual>
        <!-- caster front -->
        <collision name="caster_front_collision">
            <origin rpy=" 0 0 0" xyz="0.175 0 -0.025" />
            <geometry>
                <sphere radius="0.025" />
            </geometry>
        </collision>
        <visual name="caster_front_visual">
            <origin rpy=" 0 0 0" xyz="0.1 0 -0.025" />
            <geometry>
                <sphere radius="0.025" />
            </geometry>
        </visual>
    </link>
    <link name="link_right_wheel">
        
<inertial>
            <mass value="0.2" />
            <origin rpy="0 1.5707 1.5707" xyz="0 0 0" />
            <inertia ixx="0.000526666666667" ixy="0" ixz="0" iyy="0.000526666666667" iyz="0" izz="0.001" />
        </inertial>

        <collision name="link_right_wheel_collision">
            <origin rpy="0 1.5707 1.5707" xyz="0 0 0" />
            <geometry>
                <cylinder length="0.02" radius="0.05" />
            </geometry>
        </collision>
        <visual name="link_right_wheel_visual">
            <origin rpy="0 1.5707 1.5707" xyz="0 0 0" />
            <geometry>
                <cylinder length="0.02" radius="0.05" />
            </geometry>
            <material name="red" />
        </visual>
    </link>
    <link name="link_left_wheel">
        
<inertial>
            <mass value="0.2" />
            <origin rpy="0 1.5707 1.5707" xyz="0 0 0" />
            <inertia ixx="0.000526666666667" ixy="0" ixz="0" iyy="0.000526666666667" iyz="0" izz="0.001" />
        </inertial>

        <collision name="link_left_wheel_collision">
            <origin rpy="0 1.5707 1.5707" xyz="0 0 0" />
            <geometry>
                <cylinder length="0.02" radius="0.05" />
            </geometry>
        </collision>
        <visual name="link_left_wheel_visual">
            <origin rpy="0 1.5707 1.5707" xyz="0 0 0" />
            <geometry>
                <cylinder length="0.02" radius="0.05" />
            </geometry>
            <material name="red" />
        </visual>
    </link>
    <joint name="joint_right_wheel" type="continuous">
        <origin rpy="0 0 0" xyz="-0.025 0.075 0" />
        <child link="link_right_wheel" />
        <parent link="link_chassis" />
        <axis rpy="0 0 0" xyz="0 1 0" />
        <limit effort="10000" velocity="1000" />
        <joint_properties damping="1.0" friction="1.0" />
    </joint>
    <joint name="joint_left_wheel" type="continuous">
        <origin rpy="0 0 0" xyz="-0.025 -0.075 0" />
        <child link="link_left_wheel" />
        <parent link="link_chassis" />
        <axis rpy="0 0 0" xyz="0 1 0" />
        <limit effort="10000" velocity="1000" />
        <joint_properties damping="1.0" friction="1.0" />
    </joint>
    <link name="arm_base_link">
        
<inertial>
            <mass value="0.0125" />
            <origin rpy="0 0 0" xyz="0 0 0" />
            <inertia ixx="0.000005208333333375" ixy="0" ixz="0" iyy="0.000005208333333375" iyz="0" izz="0.000005208333333375" />
        </inertial>

        <collision>
            <origin rpy="0 0 0" xyz="0 0 0" />
            <geometry>
                <box size="0.05 0.05 0.05" />
            </geometry>
        </collision>
        <visual>
            <origin rpy="0 0 0" xyz="0 0 0" />
            <geometry>
                <box size="0.05 0.05 0.05" />
            </geometry>
            <material name="red" />
        </visual>
    </link>
    <joint name="arm_base_to_base" type="fixed">
        <origin rpy="0 0 0" xyz="0 0 0.0425" />
        <parent link="link_chassis" />
        <child link="arm_base_link" />
    </joint>
    <!-- Rest of the arm definition -->
    <link name="arm_link_01">
        
<inertial>
            <mass value="0.00625" />
            <origin rpy="0 0 0" xyz="0 0 0" />
            <inertia ixx="0.00000256975" ixy="0" ixz="0" iyy="0.00000256975" iyz="0" izz="0.00000180625" />
        </inertial>

        <collision>
            <origin rpy="0 0 0" xyz="0 0 0" />
            <geometry>
                <cylinder length="0.16" radius="0.02" />
            </geometry>
        </collision>
        <visual>
            <origin rpy="0 0 0" xyz="0 0 0" />
            <geometry>
                <cylinder length="0.16" radius="0.02" />
            </geometry>
            <material name="red" />
        </visual>
    </link>
    <joint name="arm_joint_01" type="revolute">
        <axis xyz="0 0 1" />
        <limit effort="1000.0" lower="-3.14" upper="3.14" velocity="0.2" />
        <origin rpy="0 0 0" xyz="0 0 0.1025" />
        <parent link="arm_base_link" />
        <child link="arm_link_01" />
    </joint>
    <link name="hokuyo_link">
        <collision>
            <origin rpy="0 0 0" xyz="0 0 0.00125" />
            <geometry>
                <box size="0.025 0.025 0.025" />
            </geometry>
        </collision>
        <visual>
            <origin rpy="0 0 0" xyz="0 0 0.0125" />
            <geometry>
                <box size="0.025 0.025 0.025" />
            </geometry>
            <material name="red">
                <color rgba="1 0 0 1" />
            </material>
        </visual>
        
<inertial>
            <mass value="1e-5" />
            <origin rpy="0 0 0" xyz="0 0 0" />
            <inertia ixx="1e-6" ixy="0" ixz="0" iyy="1e-6" iyz="0" izz="1e-6" />
        </inertial>

    </link>
    <joint name="hokuyo_joint" type="fixed">
        <axis xyz="0 1 0" />
        <origin rpy="0 0 0" xyz="0.14 0 0.025" />
        <parent link="link_chassis" />
        <child link="hokuyo_link" />
    </joint>
    <joint name="camera_joint" type="fixed">
        <axis xyz="0 1 0" />
        <origin rpy="0 0 0" xyz="0 0 0.1" />
        <parent link="arm_link_01" />
        <child link="camera_link" />
    </joint>
    <!-- Camera -->
    <link name="camera_link">
        <collision>
            <origin rpy="0 0 0" xyz="0.0 0.0 0.0" />
            <geometry>
                <box size="0.02 0.02 0.02" />
            </geometry>
        </collision>
        <visual>
            <origin rpy="0 0 0" xyz="0 0 0" />
            <geometry>
                <box size="0.02 0.02 0.02" />
            </geometry>
            <material name="red" />
        </visual>
        
<inertial>
            <mass value="1e-5" />
            <origin rpy="0 0 0" xyz="0 0 0" />
            <inertia ixx="1e-6" ixy="0" ixz="0" iyy="1e-6" iyz="0" izz="1e-6" />
        </inertial>

    </link>
    
<transmission name="trans_joint_right_wheel">
        <type>transmission_interface/SimpleTransmission</type>
        <joint name="joint_right_wheel">
            <hardwareInterface>hardware_interface/EffortJointInterface</hardwareInterface>
        </joint>
        <actuator name="joint_right_wheel_motor">
            <hardwareInterface>hardware_interface/EffortJointInterface</hardwareInterface>
            <mechanicalReduction>1</mechanicalReduction>
        </actuator>
    </transmission>
    <transmission name="trans_joint_left_wheel">
        <type>transmission_interface/SimpleTransmission</type>
        <joint name="joint_left_wheel">
            <hardwareInterface>hardware_interface/EffortJointInterface</hardwareInterface>
        </joint>
        <actuator name="joint_left_wheel_motor">
            <hardwareInterface>hardware_interface/EffortJointInterface</hardwareInterface>
            <mechanicalReduction>1</mechanicalReduction>
        </actuator>
    </transmission>
    <transmission name="trans_arm_joint_01">
        <type>transmission_interface/SimpleTransmission</type>
        <joint name="arm_joint_01">
            <hardwareInterface>hardware_interface/EffortJointInterface</hardwareInterface>
        </joint>
        <actuator name="arm_joint_01_motor">
            <hardwareInterface>hardware_interface/EffortJointInterface</hardwareInterface>
            <mechanicalReduction>1</mechanicalReduction>
        </actuator>
    </transmission>
    <gazebo>
        <plugin name="gazebo_ros_control" filename="libgazebo_ros_control.so">
            <robotNamespace>/</robotNamespace>
        </plugin>
    </gazebo>
</robot>
